Workbook
Name AllPoints: All!$B:$D
Name Data: Lookups!$1:$10
Name DIstanceMultiplier: Lookups!$A$14
Name FullLap: Lookups!$A$13
Name Lane1Max: Lookups!$J$2
Name Lane2Max: Lookups!$J$3
Name Lane3Max: Lookups!$J$4
Name Lane4Max: Lookups!$J$5
Name Lane5Max: Lookups!$J$6
Name Lane6Max: Lookups!$J$7
Name Lane7Max: Lookups!$J$8
Name Lane8Max: Lookups!$J$9
Name Lane9Max: Lookups!$J$10
Name OutRadius: Lookups!$B$10
Name Radius: Lookups!$B$2
Name Straight: Lookups!$A$12

Sheet Plan
S2: Measure | U2: X | V2: Y
S3: From: | T3: C | U3: =IFERROR(VLOOKUP(T3,AllPoints,2,FALSE),0) -> 0 | V3: =IFERROR(VLOOKUP(T3,AllPoints,3,FALSE),0) -> -38.99
S4: To: | T4: H-1-6 | U4: =IFERROR(VLOOKUP(T4,AllPoints,2,FALSE),0) -> 120.35709 | V4: =IFERROR(VLOOKUP(T4,AllPoints,3,FALSE),0) -> 11.988337
S5: Distance: | T5: =SQRT((U4-U3)^2+(V4-V3)^2) -> 130.70815 | U5: =ABS(U4-U3) -> 120.35709 | V5: =ABS(V4-V3) -> 50.978337

Sheet All
A1: Sheet | B1: Label | C1: X | D1: Y
A2: Landmarks | B2: =Landmarks!A3 -> X | C2: =Landmarks!B3 -> 0 | D2: =Landmarks!C3 -> 0
A3: Landmarks | B3: =Landmarks!A4 -> Y | C3: =Landmarks!B4 -> 76.89 | D3: =Landmarks!C4 -> 0
A4: Landmarks | B4: =Landmarks!A5 -> A | C4: =Landmarks!B5 -> 0 | D4: =Landmarks!C5 -> 38.99
A5: Landmarks | B5: =Landmarks!A6 -> B | C5: =Landmarks!B6 -> 76.89 | D5: =Landmarks!C6 -> 38.99
A6: Landmarks | B6: =Landmarks!A7 -> C | C6: =Landmarks!B7 -> 0 | D6: =Landmarks!C7 -> -38.99
A7: Landmarks | B7: =Landmarks!A8 -> D | C7: =Landmarks!B8 -> 76.89 | D7: =Landmarks!C8 -> -38.99
A8: Landmarks | B8: =Landmarks!A9 -> DH (SP2) | C8: =Landmarks!B9 -> 50.93 | D8: =Landmarks!C9 -> 33.19
A9: Landmarks | B9: =Landmarks!A10 -> DH (SP6) | C9: =Landmarks!B10 -> -28.62 | D9: =Landmarks!C10 -> 12.11
A10: Landmarks | B10: =Landmarks!A11 -> DH (SP7) | C10: =Landmarks!B11 -> -33.34 | D10: =Landmarks!C11 -> 0.5
A11: Landmarks | B11: =Landmarks!A12 -> NIP (A) | C11: =Landmarks!B12 -> 0 | D11: =Landmarks!C12 -> 50.59
A12: Landmarks | B12: =Landmarks!A13 -> NIP (B) | C12: =Landmarks!B13 -> 76.89 | D12: =Landmarks!C13 -> 49.53
A13: Landmarks | B13: =Landmarks!A14 -> NIP (C) | C13: =Landmarks!B14 -> 0 | D13: =Landmarks!C14 -> -49.81
... A22: Landmarks | B22: =Landmarks!A23 -> NIP (HS2) | C22: =Landmarks!B23 -> -23.11 | D22: =Landmarks!C23 -> -48.75
A24: Starts | B24: =Starts!A3 -> 200-1 | C24: =Starts!D3 -> -4.7748979e-15 | D24: =Starts!E3 -> 38.99
A25: Starts | B25: =Starts!A4 -> 200-2 | C25: =Starts!D4 -> -3.8080583 | D25: =Starts!E4 -> 40.029274
A26: Starts | B26: =Starts!A5 -> 200-3 | C26: =Starts!D5 -> -7.5856238 | D26: =Starts!E5 -> 40.729636
A27: Starts | B27: =Starts!A6 -> 200-4 | C27: =Starts!D6 -> -11.307712 | D27: =Starts!E6 -> 41.123693
A28: Starts | B28: =Starts!A7 -> 200-5 | C28: =Starts!D7 -> -14.955434 | D28: =Starts!E7 -> 41.242113
A29: Starts | B29: =Starts!A8 -> 200-6 | C29: =Starts!D8 -> -18.514837 | D29: =Starts!E8 -> 41.113366
A30: Starts | B30: =Starts!A9 -> 200-7 | C30: =Starts!D9 -> -21.975939 | D30: =Starts!E9 -> 40.763638
A31: Starts | B31: =Starts!A10 -> 200-8 | C31: =Starts!D10 -> -25.331933 | D31: =Starts!E10 -> 40.216838
A33: Starts | B33: =Starts!F3 -> 400-1 | C33: =Starts!I3 -> 76.89 | D33: =Starts!J3 -> -38.99
A34: Starts | B34: =Starts!F4 -> 400-2 | C34: =Starts!I4 -> 84.471886 | D34: =Starts!J4 -> -39.488721
A35: Starts | B35: =Starts!F5 -> 400-3 | C35: =Starts!I5 -> 91.804781 | D35: =Starts!J5 -> -38.652221
A36: Starts | B36: =Starts!F6 -> 400-4 | C36: =Starts!I6 -> 98.69609 | D36: =Starts!J6 -> -36.654017
A37: Starts | B37: =Starts!F7 -> 400-5 | C37: =Starts!I7 -> 105.00916 | D37: =Starts!J7 -> -33.673282
A38: Starts | B38: =Starts!F8 -> 400-6 | C38: =Starts!I8 -> 110.65391 | D38: =Starts!J8 -> -29.88489
A39: Starts | B39: =Starts!F9 -> 400-7 | C39: =Starts!I9 -> 115.57794 | D39: =Starts!J9 -> -25.453084
A40: Starts | B40: =Starts!F10 -> 400-8 | C40: =Starts!I10 -> 119.75851 | D40: =Starts!J10 -> -20.527819
A42: Starts | B42: =Starts!K3 -> 800-S-1 | C42: =Starts!N3 -> 76.89 | D42: =Starts!O3 -> -38.99
A43: Starts | B43: =Starts!K4 -> 800-S-2 | C43: =Starts!N4 -> 80.698058 | D43: =Starts!O4 -> -40.029274
A44: Starts | B44: =Starts!K5 -> 800-S-3 | C44: =Starts!N5 -> 84.485407 | D44: =Starts!O5 -> -40.727812
A45: Starts | B45: =Starts!K6 -> 800-S-4 | C45: =Starts!N6 -> 88.216905 | D45: =Starts!O6 -> -41.118411
A46: Starts | B46: =Starts!K7 -> 800-S-5 | C46: =Starts!N7 -> 91.938979 | D46: =Starts!O7 -> -41.208071
A47: Starts | B47: =Starts!K8 -> 800-S-6 | C47: =Starts!N8 -> 95.595271 | D47: =Starts!O8 -> -41.027075
A48: Starts | B48: =Starts!K9 -> 800-S-7 | C48: =Starts!N9 -> 99.14588 | D48: =Starts!O9 -> -40.611475
A49: Starts | B49: =Starts!K10 -> 800-S-8 | C49: =Starts!N10 -> 102.58321 | D49: =Starts!O10 -> -39.986994
A50: Starts | B50: =Starts!K11 -> 800-B-1 | C50: =Starts!N11 -> 76.89 | D50: =Starts!O11 -> 38.99
A51: Starts | B51: =Starts!K12 -> 800-B-2 | C51: =Starts!N12 -> 76.89 | D51: =Starts!O12 -> 40.21
...

Sheet Distances
A1: From | B1: From X | C1: From Y | D1: To | E1: To X | F1: To Y | G1: Distance | H1: From Survey | I1: Delta
A3: Page 2 - Tracks and Starts
A4: =Landmarks!A9 -> DH (SP2) | B4: =Landmarks!B9 -> 50.93 | C4: =Landmarks!C9 -> 33.19 | D4: =Starts!A3 -> 200-1 | E4: =Starts!D3 -> -4.7748979e-15 | F4: =Starts!E3 -> 38.99 | G4: =SQRT((E4-B4)^2+(F4-C4)^2) -> 51.259193 | H4: 51.26 | I4: =G4-H4 -> -0.00080667822
A5: =Landmarks!A9 -> DH (SP2) | B5: =Landmarks!B9 -> 50.93 | C5: =Landmarks!C9 -> 33.19 | D5: =Starts!A4 -> 200-2 | E5: =Starts!D4 -> -3.8080583 | F5: =Starts!E4 -> 40.029274 | G5: =SQRT((E5-B5)^2+(F5-C5)^2) -> 55.163672 | H5: 55.17 | I5: =G5-H5 -> -0.0063280844
A6: =Landmarks!A9 -> DH (SP2) | B6: =Landmarks!B9 -> 50.93 | C6: =Landmarks!C9 -> 33.19 | D6: =Starts!A5 -> 200-3 | E6: =Starts!D5 -> -7.5856238 | F6: =Starts!E5 -> 40.729636 | G6: =SQRT((E6-B6)^2+(F6-C6)^2) -> 58.999359 | H6: 59 | I6: =G6-H6 -> -0.00064125808
A7: =Landmarks!A12 -> NIP (A) | B7: =Landmarks!B12 -> 0 | C7: =Landmarks!C12 -> 50.59 | D7: =Starts!A6 -> 200-4 | E7: =Starts!D6 -> -11.307712 | F7: =Starts!E6 -> 41.123693 | G7: =SQRT((E7-B7)^2+(F7-C7)^2) -> 14.747044 | H7: 14.75 | I7: =G7-H7 -> -0.0029558982
A8: =Landmarks!A12 -> NIP (A) | B8: =Landmarks!B12 -> 0 | C8: =Landmarks!C12 -> 50.59 | D8: =Starts!A7 -> 200-5 | E8: =Starts!D7 -> -14.955434 | F8: =Starts!E7 -> 41.242113 | G8: =SQRT((E8-B8)^2+(F8-C8)^2) -> 17.636553 | H8: 17.64 | I8: =G8-H8 -> -0.0034469607
A9: =Landmarks!A12 -> NIP (A) | B9: =Landmarks!B12 -> 0 | C9: =Landmarks!C12 -> 50.59 | D9: =Starts!A8 -> 200-6 | E9: =Starts!D8 -> -18.514837 | F9: =Starts!E8 -> 41.113366 | G9: =SQRT((E9-B9)^2+(F9-C9)^2) -> 20.799177 | H9: 20.8 | I9: =G9-H9 -> -0.00082250281
A10: =Landmarks!A12 -> NIP (A) | B10: =Landmarks!B12 -> 0 | C10: =Landmarks!C12 -> 50.59 | D10: =Starts!A9 -> 200-7 | E10: =Starts!D9 -> -21.975939 | F10: =Starts!E9 -> 40.763638 | G10: =SQRT((E10-B10)^2+(F10-C10)^2) -> 24.072791 | H10: 24.1 | I10: =G10-H10 -> -0.02720902
A11: =Landmarks!A12 -> NIP (A) | B11: =Landmarks!B12 -> 0 | C11: =Landmarks!C12 -> 50.59 | D11: =Starts!A10 -> 200-8 | E11: =Starts!D10 -> -25.331933 | F11: =Starts!E10 -> 40.216838 | G11: =SQRT((E11-B11)^2+(F11-C11)^2) -> 27.373515 | H11: 27.37 | I11: =G11-H11 -> 0.0035149926
A12: =Landmarks!A9 -> DH (SP2) | B12: =Landmarks!B9 -> 50.93 | C12: =Landmarks!C9 -> 33.19 | D12: =Starts!P3 -> 3000-1 | E12: =Starts!S3 -> -4.7748979e-15 | F12: =Starts!T3 -> 38.99 | G12: =SQRT((E12-B12)^2+(F12-C12)^2) -> 51.259193 | H12: 51.26 | I12: =G12-H12 -> -0.00080667822
A13: =Landmarks!A9 -> DH (SP2) | B13: =Landmarks!B9 -> 50.93 | C13: =Landmarks!C9 -> 33.19 | D13: =Starts!P4 -> 3000-2 | E13: =Starts!S4 -> -0.17090853 | F13: =Starts!T4 -> 40.209637 | G13: =SQRT((E13-B13)^2+(F13-C13)^2) -> 51.580792 | H13: 51.58 | I13: =G13-H13 -> 0.00079248752
A14: =Landmarks!A9 -> DH (SP2) | B14: =Landmarks!B9 -> 50.93 | C14: =Landmarks!C9 -> 33.19 | D14: =Starts!P5 -> 3000-3 | E14: =Starts!S5 -> -0.52196853 | F14: =Starts!T5 -> 41.426712 | G14: =SQRT((E14-B14)^2+(F14-C14)^2) -> 52.107087 | H14: 52.11 | I14: =G14-H14 -> -0.0029132776
A15: =Landmarks!A9 -> DH (SP2) | B15: =Landmarks!B9 -> 50.93 | C15: =Landmarks!C9 -> 33.19 | D15: =Starts!P6 -> 3000-4 | E15: =Starts!S6 -> -1.0323031 | F15: =Starts!T6 -> 42.637505 | G15: =SQRT((E15-B15)^2+(F15-C15)^2) -> 52.814168 | H15: 52.81 | I15: =G15-H15 -> 0.0041675905
A16: =Landmarks!A9 -> DH (SP2) | B16: =Landmarks!B9 -> 50.93 | C16: =Landmarks!C9 -> 33.19 | D16: =Starts!P7 -> 3000-5 | E16: =Starts!S7 -> -1.6321688 | F16: =Starts!T7 -> 43.839627 | G16: =SQRT((E16-B16)^2+(F16-C16)^2) -> 53.63018 | H16: 53.63 | I16: =G16-H16 -> 0.00017950198
A17: =Landmarks!A9 -> DH (SP2) | B17: =Landmarks!B9 -> 50.93 | C17: =Landmarks!C9 -> 33.19 | D17: =Starts!P8 -> 3000-6 | E17: =Starts!S8 -> -2.3412883 | F17: =Starts!T8 -> 45.029174 | G17: =SQRT((E17-B17)^2+(F17-C17)^2) -> 54.57102 | H17: 54.57 | I17: =G17-H17 -> 0.0010196482
A18: =Landmarks!A9 -> DH (SP2) | B18: =Landmarks!B9 -> 50.93 | C18: =Landmarks!C9 -> 33.19 | D18: =Starts!P9 -> 3000-7 | E18: =Starts!S9 -> -3.1593634 | F18: =Starts!T9 -> 46.202105 | G18: =SQRT((E18-B18)^2+(F18-C18)^2) -> 55.632492 | H18: 55.63 | I18: =G18-H18 -> 0.0024915426
A19: =Landmarks!A9 -> DH (SP2) | B19: =Landmarks!B9 -> 50.93 | C19: =Landmarks!C9 -> 33.19 | D19: =Starts!P10 -> 3000-8 | E19: =Starts!S10 -> -4.1157164 | F19: =Starts!T10 -> 47.351471 | G19: =SQRT((E19-B19)^2+(F19-C19)^2) -> 56.838175 | H19: 56.84 | I19: =G19-H19 -> -0.001824896
A20: =Landmarks!A9 -> DH (SP2) | B20: =Landmarks!B9 -> 50.93 | C20: =Landmarks!C9 -> 33.19 | D20: =Starts!P11 -> 3000-9 | E20: =Starts!S11 -> -5.2392856 | F20: =Starts!T11 -> 48.467643 | G20: =SQRT((E20-B20)^2+(F20-C20)^2) -> 58.209922 | H20: 58.21 | I20: =G20-H20 -> -7.809167e-05
A21: =Landmarks!A9 -> DH (SP2) | B21: =Landmarks!B9 -> 50.93 | C21: =Landmarks!C9 -> 33.19 | D21: =Starts!K11 -> 800-B-1 | E21: =Starts!N11 -> 76.89 | F21: =Starts!O11 -> 38.99 | G21: =SQRT((E21-B21)^2+(F21-C21)^2) -> 26.60003 | H21: 26.6 | I21: =G21-H21 -> 3.0075171e-05
A22: =Landmarks!A9 -> DH (SP2) | B22: =Landmarks!B9 -> 50.93 | C22: =Landmarks!C9 -> 33.19 | D22: =Starts!K12 -> 800-B-2 | E22: =Starts!N12 -> 76.89 | F22: =Starts!O12 -> 40.21 | G22: =SQRT((E22-B22)^2+(F22-C22)^2) -> 26.892415 | H22: 26.89 | I22: =G22-H22 -> 0.0024152876
A23: =Landmarks!A9 -> DH (SP2) | B23: =Landmarks!B9 -> 50.93 | C23: =Landmarks!C9 -> 33.19 | D23: =Starts!K13 -> 800-B-3 | E23: =Starts!N13 -> 76.88 | F23: =Starts!O13 -> 41.43 | G23: =SQRT((E23-B23)^2+(F23-C23)^2) -> 27.226827 | H23: 27.21 | I23: =G23-H23 -> 0.016826844
A24: =Landmarks!A9 -> DH (SP2) | B24: =Landmarks!B9 -> 50.93 | C24: =Landmarks!C9 -> 33.19 | D24: =Starts!K14 -> 800-B-4 | E24: =Starts!N14 -> 76.87 | F24: =Starts!O14 -> 42.65 | G24: =SQRT((E24-B24)^2+(F24-C24)^2) -> 27.611143 | H24: 27.64 | I24: =G24-H24 -> -0.028857322
A25: =Landmarks!A9 -> DH (SP2) | B25: =Landmarks!B9 -> 50.93 | C25: =Landmarks!C9 -> 33.19 | D25: =Starts!K16 -> 800-B-6 | E25: =Starts!N16 -> 76.68 | F25: =Starts!O16 -> 45.09 | G25: =SQRT((E25-B25)^2+(F25-C25)^2) -> 28.36675 | H25: 28.36 | I25: =G25-H25 -> 0.006749902
A26: =Landmarks!A9 -> DH (SP2) | B26: =Landmarks!B9 -> 50.93 | C26: =Landmarks!C9 -> 33.19 | D26: =Starts!K17 -> 800-B-7 | E26: =Starts!N17 -> 76.57 | F26: =Starts!O17 -> 46.31 | G26: =SQRT((E26-B26)^2+(F26-C26)^2) -> 28.801805 | H26: 28.81 | I26: =G26-H26 -> -0.008194501
A27: =Landmarks!A9 -> DH (SP2) | B27: =Landmarks!B9 -> 50.93 | C27: =Landmarks!C9 -> 33.19 | D27: =Starts!K18 -> 800-B-8 | E27: =Starts!N18 -> 76.46 | F27: =Starts!O18 -> 47.53 | G27: =SQRT((E27-B27)^2+(F27-C27)^2) -> 29.281675 | H27: 29.28 | I27: =G27-H27 -> 0.001675157
A28: =Landmarks!A9 -> DH (SP2) | B28: =Landmarks!B9 -> 50.93 | C28: =Landmarks!C9 -> 33.19 | D28: =Starts!K19 -> 800-B-9 | E28: =Starts!N19 -> 76.33 | F28: =Starts!O19 -> 48.75 | G28: =SQRT((E28-B28)^2+(F28-C28)^2) -> 29.787138 | H28: 29.79 | I28: =G28-H28 -> -0.002861836
A29: =Landmarks!A17 -> NIC (1500) | B29: =Landmarks!B17 -> 119.75 | C29: =Landmarks!C17 -> 25.67 | D29: =Starts!U3 -> 1500-1 | E29: =Starts!X3 -> 98.57624 | F29: =Starts!Y3 -> 32.402579 | G29: =SQRT((E29-B29)^2+(F29-C29)^2) -> 22.218365 | H29: 22.22 | I29: =G29-H29 -> -0.0016349347
A30: =Landmarks!A17 -> NIC (1500) | B30: =Landmarks!B17 -> 119.75 | C30: =Landmarks!C17 -> 25.67 | D30: =Starts!U4 -> 1500-2 | E30: =Starts!X4 -> 99.109192 | F30: =Starts!Y4 -> 33.513454 | G30: =SQRT((E30-B30)^2+(F30-C30)^2) -> 22.080823 | H30: 22.08 | I30: =G30-H30 -> 0.00082300511
A31: =Landmarks!A17 -> NIC (1500) | B31: =Landmarks!B17 -> 119.75 | C31: =Landmarks!C17 -> 25.67 | D31: =Starts!U5 -> 1500-3 | E31: =Starts!X5 -> 99.503065 | F31: =Starts!Y5 -> 34.714466 | G31: =SQRT((E31-B31)^2+(F31-C31)^2) -> 22.175228 | H31: 22.18 | I31: =G31-H31 -> -0.0047719627
A32: =Landmarks!A17 -> NIC (1500) | B32: =Landmarks!B17 -> 119.75 | C32: =Landmarks!C17 -> 25.67 | D32: =Starts!U6 -> 1500-4 | E32: =Starts!X6 -> 99.752803 | F32: =Starts!Y6 -> 36.004371 | G32: =SQRT((E32-B32)^2+(F32-C32)^2) -> 22.509712 | H32: 22.51 | I32: =G32-H32 -> -0.0002884757
A33: =Landmarks!A17 -> NIC (1500) | B33: =Landmarks!B17 -> 119.75 | C33: =Landmarks!C17 -> 25.67 | D33: =Starts!U7 -> 1500-5 | E33: =Starts!X7 -> 99.91485 | F33: =Starts!Y7 -> 37.34211 | G33: =SQRT((E33-B33)^2+(F33-C33)^2) -> 23.014589 | H33: 23.01 | I33: =G33-H33 -> 0.0045891176
A34: =Landmarks!A17 -> NIC (1500) | B34: =Landmarks!B17 -> 119.75 | C34: =Landmarks!C17 -> 25.67 | D34: =Starts!U8 -> 1500-6 | E34: =Starts!X8 -> 100.01316 | F34: =Starts!Y8 -> 38.709527 | G34: =SQRT((E34-B34)^2+(F34-C34)^2) -> 23.655276 | H34: 23.66 | I34: =G34-H34 -> -0.0047241063
A35: =Landmarks!A17 -> NIC (1500) | B35: =Landmarks!B17 -> 119.75 | C35: =Landmarks!C17 -> 25.67 | D35: =Starts!U9 -> 1500-7 | E35: =Starts!X9 -> 99.960397 | F35: =Starts!Y9 -> 40.154363 | G35: =SQRT((E35-B35)^2+(F35-C35)^2) -> 24.523971 | H35: 24.52 | I35: =G35-H35 -> 0.0039711468
A36: =Landmarks!A17 -> NIC (1500) | B36: =Landmarks!B17 -> 119.75 | C36: =Landmarks!C17 -> 25.67 | D36: =Starts!U10 -> 1500-8 | E36: =Starts!X10 -> 99.761628 | F36: =Starts!Y10 -> 41.665208 | G36: =SQRT((E36-B36)^2+(F36-C36)^2) -> 25.600424 | H36: 25.6 | I36: =G36-H36 -> 0.00042373635
A37: =Landmarks!A17 -> NIC (1500) | B37: =Landmarks!B17 -> 119.75 | C37: =Landmarks!C17 -> 25.67 | D37: =Starts!U11 -> 1500-9 | E37: =Starts!X11 -> 99.377915 | F37: =Starts!Y11 -> 43.253395 | G37: =SQRT((E37-B37)^2+(F37-C37)^2) -> 26.91092 | H37: 26.91 | I37: =G37-H37 -> 0.00091981239
A38: =Landmarks!A18 -> NIC (800) | B38: =Landmarks!B18 -> 94.11 | C38: =Landmarks!C18 -> -47.14 | D38: =Starts!K3 -> 800-S-1 | E38: =Starts!N3 -> 76.89 | F38: =Starts!O3 -> -38.99 | G38: =SQRT((E38-B38)^2+(F38-C38)^2) -> 19.05127 | H38: 19.05 | I38: =G38-H38 -> 0.0012702989
A39: =Landmarks!A19 -> NIC (400) | B39: =Landmarks!B19 -> 108.67 | C39: =Landmarks!C19 -> -38.77 | D39: =Starts!K4 -> 800-S-2 | E39: =Starts!N4 -> 80.698058 | F39: =Starts!O4 -> -40.029274 | G39: =SQRT((E39-B39)^2+(F39-C39)^2) -> 28.000273 | H39: 28 | I39: =G39-H39 -> 0.00027309236
A40: =Landmarks!A19 -> NIC (400) | B40: =Landmarks!B19 -> 108.67 | C40: =Landmarks!C19 -> -38.77 | D40: =Starts!K5 -> 800-S-3 | E40: =Starts!N5 -> 84.485407 | F40: =Starts!O5 -> -40.727812 | G40: =SQRT((E40-B40)^2+(F40-C40)^2) -> 24.263709 | H40: 24.24 | I40: =G40-H40 -> 0.023708557
A41: =Landmarks!A19 -> NIC (400) | B41: =Landmarks!B19 -> 108.67 | C41: =Landmarks!C19 -> -38.77 | D41: =Starts!K6 -> 800-S-4 | E41: =Starts!N6 -> 88.216905 | F41: =Starts!O6 -> -41.118411 | G41: =SQRT((E41-B41)^2+(F41-C41)^2) -> 20.587475 | H41: 20.53 | I41: =G41-H41 -> 0.057475174
...

Sheet Lookups
A1: Lane | B1: Inside Radius | C1: Line of Running Radius | D1: Distance A | E1: Distance B | F1: Distance C | G1: Distance D | H1: Distance A+B | I1: Distance A+B+C | J1: Distance A+B+C+D | K1: Bend Delta
A2: 1 | B2: 38.99 | C2: =B2+0.2 -> 39.19 | D2: =Straight -> 76.89 | E2: =PI()*C2 -> 123.11902 | F2: =Straight -> 76.89 | G2: =PI()*C2 -> 123.11902 | H2: =D2+E2 -> 200.00902 | I2: =D2+E2+F2 -> 276.89902 | J2: =D2+E2+F2+G2 -> 400.01803 | K2: =E2-E$2 -> 0 | L2: =J2-K2 -> 400.01803
A3: 2 | B3: =B2+1.22 -> 40.21 | C3: =B3+0.2 -> 40.41 | D3: =Straight -> 76.89 | E3: =PI()*C3 -> 126.95176 | F3: =Straight -> 76.89 | G3: =PI()*C3 -> 126.95176 | H3: =D3+E3 -> 203.84176 | I3: =D3+E3+F3 -> 280.73176 | J3: =D3+E3+F3+G3 -> 407.68352 | K3: =E3-E$2 -> 3.832743 | L3: =J3-K3 -> 403.85078
A4: 3 | B4: =B3+1.22 -> 41.43 | C4: =B4+0.2 -> 41.63 | D4: =Straight -> 76.89 | E4: =PI()*C4 -> 130.7845 | F4: =Straight -> 76.89 | G4: =PI()*C4 -> 130.7845 | H4: =D4+E4 -> 207.6745 | I4: =D4+E4+F4 -> 284.5645 | J4: =D4+E4+F4+G4 -> 415.349 | K4: =E4-E$2 -> 7.6654861 | L4: =J4-K4 -> 407.68352
A5: 4 | B5: =B4+1.22 -> 42.65 | C5: =B5+0.2 -> 42.85 | D5: =Straight -> 76.89 | E5: =PI()*C5 -> 134.61725 | F5: =Straight -> 76.89 | G5: =PI()*C5 -> 134.61725 | H5: =D5+E5 -> 211.50725 | I5: =D5+E5+F5 -> 288.39725 | J5: =D5+E5+F5+G5 -> 423.01449 | K5: =E5-E$2 -> 11.498229 | L5: =J5-K5 -> 411.51626
A6: 5 | B6: =B5+1.22 -> 43.87 | C6: =B6+0.2 -> 44.07 | D6: =Straight -> 76.89 | E6: =PI()*C6 -> 138.44999 | F6: =Straight -> 76.89 | G6: =PI()*C6 -> 138.44999 | H6: =D6+E6 -> 215.33999 | I6: =D6+E6+F6 -> 292.22999 | J6: =D6+E6+F6+G6 -> 430.67998 | K6: =E6-E$2 -> 15.330972 | L6: =J6-K6 -> 415.349
A7: 6 | B7: =B6+1.22 -> 45.09 | C7: =B7+0.2 -> 45.29 | D7: =Straight -> 76.89 | E7: =PI()*C7 -> 142.28273 | F7: =Straight -> 76.89 | G7: =PI()*C7 -> 142.28273 | H7: =D7+E7 -> 219.17273 | I7: =D7+E7+F7 -> 296.06273 | J7: =D7+E7+F7+G7 -> 438.34546 | K7: =E7-E$2 -> 19.163715 | L7: =J7-K7 -> 419.18175
A8: 7 | B8: =B7+1.22 -> 46.31 | C8: =B8+0.2 -> 46.51 | D8: =Straight -> 76.89 | E8: =PI()*C8 -> 146.11547 | F8: =Straight -> 76.89 | G8: =PI()*C8 -> 146.11547 | H8: =D8+E8 -> 223.00547 | I8: =D8+E8+F8 -> 299.89547 | J8: =D8+E8+F8+G8 -> 446.01095 | K8: =E8-E$2 -> 22.996458 | L8: =J8-K8 -> 423.01449
A9: 8 | B9: =B8+1.22 -> 47.53 | C9: =B9+0.2 -> 47.73 | D9: =Straight -> 76.89 | E9: =PI()*C9 -> 149.94822 | F9: =Straight -> 76.89 | G9: =PI()*C9 -> 149.94822 | H9: =D9+E9 -> 226.83822 | I9: =D9+E9+F9 -> 303.72822 | J9: =D9+E9+F9+G9 -> 453.67643 | K9: =E9-E$2 -> 26.829201 | L9: =J9-K9 -> 426.84723
A10: 9 | B10: =B9+1.22 -> 48.75 | C10: =B10+0.2 -> 48.95 | D10: =Straight -> 76.89 | E10: =PI()*C10 -> 153.78096 | F10: =Straight -> 76.89 | G10: =PI()*C10 -> 153.78096 | H10: =D10+E10 -> 230.67096 | I10: =D10+E10+F10 -> 307.56096 | J10: =D10+E10+F10+G10 -> 461.34192 | K10: =E10-E$2 -> 30.661944 | L10: =J10-K10 -> 430.67998
A12: 76.89
A13: =J2 -> 400.01803
A14: =FullLap/400 -> 1.0000451
A16: Calculation Template
A17: 200
A18: =DIstanceMultiplier*A17 -> 200.00902 | B18: Lane | C18: X | D18: Y
A19: =A18 -> 200.00902 | B19: 1 | C19: =(Straight-(IF(A19>VLOOKUP(B19,Data,4,FALSE),1,A19/VLOOKUP(B19,Data,4,FALSE)))*Straight+(IF(A19>VLOOKUP(B19,Data,9,FALSE),1,IF(A19>VLOOKUP(B19,Data,8,FALSE),(A19-VLOOKUP(B19,Data,8,FALSE))/VLOOKUP(B19,Data,6,FALSE),0)))*Straight)-VLOOKUP(B19,Data,2,FALSE)*SIN(RADIANS(180*(IF(A19>VLOOKUP(B19,Data,8,FALSE),1,IF(A19>VLOOKUP(B19,Data,4,FALSE),(A19-VLOOKUP(B19,Data,4,FALSE))/VLOOKUP(B19,Data,5,FALSE),0)))+180*(IF(A19>VLOOKUP(B19,Data,10,FALSE),1,IF(A19>VLOOKUP(B19,Data,9,FALSE),(A19-VLOOKUP(B19,Data,9,FALSE))/VLOOKUP(B19,Data,7,FALSE),0))))) -> -4.7748979e-15 | D19: =-VLOOKUP(B19,Data,2,FALSE)*COS(RADIANS(180*(IF(A19>VLOOKUP(B19,Data,8,FALSE),1,IF(A19>VLOOKUP(B19,Data,4,FALSE),(A19-VLOOKUP(B19,Data,4,FALSE))/VLOOKUP(B19,Data,5,FALSE),0)))+180*(IF(A19>VLOOKUP(B19,Data,10,FALSE),1,IF(A19>VLOOKUP(B19,Data,9,FALSE),(A19-VLOOKUP(B19,Data,9,FALSE))/VLOOKUP(B19,Data,7,FALSE),0))))) -> 38.99
A20: =A19 -> 200.00902 | B20: 2 | C20: =(Straight-(IF(A20>VLOOKUP(B20,Data,4,FALSE),1,A20/VLOOKUP(B20,Data,4,FALSE)))*Straight+(IF(A20>VLOOKUP(B20,Data,9,FALSE),1,IF(A20>VLOOKUP(B20,Data,8,FALSE),(A20-VLOOKUP(B20,Data,8,FALSE))/VLOOKUP(B20,Data,6,FALSE),0)))*Straight)-VLOOKUP(B20,Data,2,FALSE)*SIN(RADIANS(180*(IF(A20>VLOOKUP(B20,Data,8,FALSE),1,IF(A20>VLOOKUP(B20,Data,4,FALSE),(A20-VLOOKUP(B20,Data,4,FALSE))/VLOOKUP(B20,Data,5,FALSE),0)))+180*(IF(A20>VLOOKUP(B20,Data,10,FALSE),1,IF(A20>VLOOKUP(B20,Data,9,FALSE),(A20-VLOOKUP(B20,Data,9,FALSE))/VLOOKUP(B20,Data,7,FALSE),0))))) -> -3.8080583 | D20: =-VLOOKUP(B20,Data,2,FALSE)*COS(RADIANS(180*(IF(A20>VLOOKUP(B20,Data,8,FALSE),1,IF(A20>VLOOKUP(B20,Data,4,FALSE),(A20-VLOOKUP(B20,Data,4,FALSE))/VLOOKUP(B20,Data,5,FALSE),0)))+180*(IF(A20>VLOOKUP(B20,Data,10,FALSE),1,IF(A20>VLOOKUP(B20,Data,9,FALSE),(A20-VLOOKUP(B20,Data,9,FALSE))/VLOOKUP(B20,Data,7,FALSE),0))))) -> 40.029274
A21: =A20 -> 200.00902 | B21: 3 | C21: =(Straight-(IF(A21>VLOOKUP(B21,Data,4,FALSE),1,A21/VLOOKUP(B21,Data,4,FALSE)))*Straight+(IF(A21>VLOOKUP(B21,Data,9,FALSE),1,IF(A21>VLOOKUP(B21,Data,8,FALSE),(A21-VLOOKUP(B21,Data,8,FALSE))/VLOOKUP(B21,Data,6,FALSE),0)))*Straight)-VLOOKUP(B21,Data,2,FALSE)*SIN(RADIANS(180*(IF(A21>VLOOKUP(B21,Data,8,FALSE),1,IF(A21>VLOOKUP(B21,Data,4,FALSE),(A21-VLOOKUP(B21,Data,4,FALSE))/VLOOKUP(B21,Data,5,FALSE),0)))+180*(IF(A21>VLOOKUP(B21,Data,10,FALSE),1,IF(A21>VLOOKUP(B21,Data,9,FALSE),(A21-VLOOKUP(B21,Data,9,FALSE))/VLOOKUP(B21,Data,7,FALSE),0))))) -> -7.5856238 | D21: =-VLOOKUP(B21,Data,2,FALSE)*COS(RADIANS(180*(IF(A21>VLOOKUP(B21,Data,8,FALSE),1,IF(A21>VLOOKUP(B21,Data,4,FALSE),(A21-VLOOKUP(B21,Data,4,FALSE))/VLOOKUP(B21,Data,5,FALSE),0)))+180*(IF(A21>VLOOKUP(B21,Data,10,FALSE),1,IF(A21>VLOOKUP(B21,Data,9,FALSE),(A21-VLOOKUP(B21,Data,9,FALSE))/VLOOKUP(B21,Data,7,FALSE),0))))) -> 40.729636
A22: =A21 -> 200.00902 | B22: 4 | C22: =(Straight-(IF(A22>VLOOKUP(B22,Data,4,FALSE),1,A22/VLOOKUP(B22,Data,4,FALSE)))*Straight+(IF(A22>VLOOKUP(B22,Data,9,FALSE),1,IF(A22>VLOOKUP(B22,Data,8,FALSE),(A22-VLOOKUP(B22,Data,8,FALSE))/VLOOKUP(B22,Data,6,FALSE),0)))*Straight)-VLOOKUP(B22,Data,2,FALSE)*SIN(RADIANS(180*(IF(A22>VLOOKUP(B22,Data,8,FALSE),1,IF(A22>VLOOKUP(B22,Data,4,FALSE),(A22-VLOOKUP(B22,Data,4,FALSE))/VLOOKUP(B22,Data,5,FALSE),0)))+180*(IF(A22>VLOOKUP(B22,Data,10,FALSE),1,IF(A22>VLOOKUP(B22,Data,9,FALSE),(A22-VLOOKUP(B22,Data,9,FALSE))/VLOOKUP(B22,Data,7,FALSE),0))))) -> -11.307712 | D22: =-VLOOKUP(B22,Data,2,FALSE)*COS(RADIANS(180*(IF(A22>VLOOKUP(B22,Data,8,FALSE),1,IF(A22>VLOOKUP(B22,Data,4,FALSE),(A22-VLOOKUP(B22,Data,4,FALSE))/VLOOKUP(B22,Data,5,FALSE),0)))+180*(IF(A22>VLOOKUP(B22,Data,10,FALSE),1,IF(A22>VLOOKUP(B22,Data,9,FALSE),(A22-VLOOKUP(B22,Data,9,FALSE))/VLOOKUP(B22,Data,7,FALSE),0))))) -> 41.123693
A23: =A22 -> 200.00902 | B23: 5 | C23: =(Straight-(IF(A23>VLOOKUP(B23,Data,4,FALSE),1,A23/VLOOKUP(B23,Data,4,FALSE)))*Straight+(IF(A23>VLOOKUP(B23,Data,9,FALSE),1,IF(A23>VLOOKUP(B23,Data,8,FALSE),(A23-VLOOKUP(B23,Data,8,FALSE))/VLOOKUP(B23,Data,6,FALSE),0)))*Straight)-VLOOKUP(B23,Data,2,FALSE)*SIN(RADIANS(180*(IF(A23>VLOOKUP(B23,Data,8,FALSE),1,IF(A23>VLOOKUP(B23,Data,4,FALSE),(A23-VLOOKUP(B23,Data,4,FALSE))/VLOOKUP(B23,Data,5,FALSE),0)))+180*(IF(A23>VLOOKUP(B23,Data,10,FALSE),1,IF(A23>VLOOKUP(B23,Data,9,FALSE),(A23-VLOOKUP(B23,Data,9,FALSE))/VLOOKUP(B23,Data,7,FALSE),0))))) -> -14.955434 | D23: =-VLOOKUP(B23,Data,2,FALSE)*COS(RADIANS(180*(IF(A23>VLOOKUP(B23,Data,8,FALSE),1,IF(A23>VLOOKUP(B23,Data,4,FALSE),(A23-VLOOKUP(B23,Data,4,FALSE))/VLOOKUP(B23,Data,5,FALSE),0)))+180*(IF(A23>VLOOKUP(B23,Data,10,FALSE),1,IF(A23>VLOOKUP(B23,Data,9,FALSE),(A23-VLOOKUP(B23,Data,9,FALSE))/VLOOKUP(B23,Data,7,FALSE),0))))) -> 41.242113
A24: =A23 -> 200.00902 | B24: 6 | C24: =(Straight-(IF(A24>VLOOKUP(B24,Data,4,FALSE),1,A24/VLOOKUP(B24,Data,4,FALSE)))*Straight+(IF(A24>VLOOKUP(B24,Data,9,FALSE),1,IF(A24>VLOOKUP(B24,Data,8,FALSE),(A24-VLOOKUP(B24,Data,8,FALSE))/VLOOKUP(B24,Data,6,FALSE),0)))*Straight)-VLOOKUP(B24,Data,2,FALSE)*SIN(RADIANS(180*(IF(A24>VLOOKUP(B24,Data,8,FALSE),1,IF(A24>VLOOKUP(B24,Data,4,FALSE),(A24-VLOOKUP(B24,Data,4,FALSE))/VLOOKUP(B24,Data,5,FALSE),0)))+180*(IF(A24>VLOOKUP(B24,Data,10,FALSE),1,IF(A24>VLOOKUP(B24,Data,9,FALSE),(A24-VLOOKUP(B24,Data,9,FALSE))/VLOOKUP(B24,Data,7,FALSE),0))))) -> -18.514837 | D24: =-VLOOKUP(B24,Data,2,FALSE)*COS(RADIANS(180*(IF(A24>VLOOKUP(B24,Data,8,FALSE),1,IF(A24>VLOOKUP(B24,Data,4,FALSE),(A24-VLOOKUP(B24,Data,4,FALSE))/VLOOKUP(B24,Data,5,FALSE),0)))+180*(IF(A24>VLOOKUP(B24,Data,10,FALSE),1,IF(A24>VLOOKUP(B24,Data,9,FALSE),(A24-VLOOKUP(B24,Data,9,FALSE))/VLOOKUP(B24,Data,7,FALSE),0))))) -> 41.113366
A25: =A24 -> 200.00902 | B25: 7 | C25: =(Straight-(IF(A25>VLOOKUP(B25,Data,4,FALSE),1,A25/VLOOKUP(B25,Data,4,FALSE)))*Straight+(IF(A25>VLOOKUP(B25,Data,9,FALSE),1,IF(A25>VLOOKUP(B25,Data,8,FALSE),(A25-VLOOKUP(B25,Data,8,FALSE))/VLOOKUP(B25,Data,6,FALSE),0)))*Straight)-VLOOKUP(B25,Data,2,FALSE)*SIN(RADIANS(180*(IF(A25>VLOOKUP(B25,Data,8,FALSE),1,IF(A25>VLOOKUP(B25,Data,4,FALSE),(A25-VLOOKUP(B25,Data,4,FALSE))/VLOOKUP(B25,Data,5,FALSE),0)))+180*(IF(A25>VLOOKUP(B25,Data,10,FALSE),1,IF(A25>VLOOKUP(B25,Data,9,FALSE),(A25-VLOOKUP(B25,Data,9,FALSE))/VLOOKUP(B25,Data,7,FALSE),0))))) -> -21.975939 | D25: =-VLOOKUP(B25,Data,2,FALSE)*COS(RADIANS(180*(IF(A25>VLOOKUP(B25,Data,8,FALSE),1,IF(A25>VLOOKUP(B25,Data,4,FALSE),(A25-VLOOKUP(B25,Data,4,FALSE))/VLOOKUP(B25,Data,5,FALSE),0)))+180*(IF(A25>VLOOKUP(B25,Data,10,FALSE),1,IF(A25>VLOOKUP(B25,Data,9,FALSE),(A25-VLOOKUP(B25,Data,9,FALSE))/VLOOKUP(B25,Data,7,FALSE),0))))) -> 40.763638
A26: =A25 -> 200.00902 | B26: 8 | C26: =(Straight-(IF(A26>VLOOKUP(B26,Data,4,FALSE),1,A26/VLOOKUP(B26,Data,4,FALSE)))*Straight+(IF(A26>VLOOKUP(B26,Data,9,FALSE),1,IF(A26>VLOOKUP(B26,Data,8,FALSE),(A26-VLOOKUP(B26,Data,8,FALSE))/VLOOKUP(B26,Data,6,FALSE),0)))*Straight)-VLOOKUP(B26,Data,2,FALSE)*SIN(RADIANS(180*(IF(A26>VLOOKUP(B26,Data,8,FALSE),1,IF(A26>VLOOKUP(B26,Data,4,FALSE),(A26-VLOOKUP(B26,Data,4,FALSE))/VLOOKUP(B26,Data,5,FALSE),0)))+180*(IF(A26>VLOOKUP(B26,Data,10,FALSE),1,IF(A26>VLOOKUP(B26,Data,9,FALSE),(A26-VLOOKUP(B26,Data,9,FALSE))/VLOOKUP(B26,Data,7,FALSE),0))))) -> -25.331933 | D26: =-VLOOKUP(B26,Data,2,FALSE)*COS(RADIANS(180*(IF(A26>VLOOKUP(B26,Data,8,FALSE),1,IF(A26>VLOOKUP(B26,Data,4,FALSE),(A26-VLOOKUP(B26,Data,4,FALSE))/VLOOKUP(B26,Data,5,FALSE),0)))+180*(IF(A26>VLOOKUP(B26,Data,10,FALSE),1,IF(A26>VLOOKUP(B26,Data,9,FALSE),(A26-VLOOKUP(B26,Data,9,FALSE))/VLOOKUP(B26,Data,7,FALSE),0))))) -> 40.216838
A28: Lane Widths
B29: 1 | C29: 0
B30: 2 | C30: =C29+1.22 -> 1.22
B31: 3 | C31: =C30+1.22 -> 2.44
B32: 4 | C32: =C31+1.22 -> 3.66
B33: 5 | C33: =C32+1.22 -> 4.88
B34: 6 | C34: =C33+1.22 -> 6.1
B35: 7 | C35: =C34+1.22 -> 7.32
B36: 8 | C36: =C35+1.22 -> 8.54
B37: 9 | C37: =C36+1.22 -> 9.76
B38: 10 | C38: =C37+1.22 -> 10.98
B39: 11 | C39: =C38+1.22 -> 12.2

Sheet Lanes
A1: =CONCATENATE("Lane ",C3) -> Lane 1 | F1: =CONCATENATE("Lane ",H3) -> Lane 2 | K1: =CONCATENATE("Lane ",M3) -> Lane 3 | P1: =CONCATENATE("Lane ",R3) -> Lane 4 | U1: =CONCATENATE("Lane ",W3) -> Lane 5 | Z1: =CONCATENATE("Lane ",AB3) -> Lane 6 | AE1: =CONCATENATE("Lane ",AG3) -> Lane 7 | AJ1: =CONCATENATE("Lane ",AL3) -> Lane 8 | AO1: =CONCATENATE("Lane ",AQ3) -> Lane 9 | AT1: Finish | AX1: Home Straight Start
B2: Dist | C2: Lane | D2: X | E2: Y | G2: Dist | H2: Lane | I2: X | J2: Y | L2: Dist | M2: Lane | N2: X | O2: Y | Q2: Dist | R2: Lane | S2: X | T2: Y | V2: Dist | W2: Lane | X2: X | Y2: Y | AA2: Dist | AB2: Lane | AC2: X | AD2: Y | AF2: Dist | AG2: Lane | AH2: X | AI2: Y | AK2: Dist | AL2: Lane | AM2: X | AN2: Y | AP2: Dist | AQ2: Lane | AR2: X | AS2: Y | AT2: Dist | AU2: Lane | AV2: X | AW2: Y | AX2: X | AY2: Y
B3: 0 | C3: 1 | D3: =(Straight-(IF(B3>VLOOKUP(C3,Data,4,FALSE),1,B3/VLOOKUP(C3,Data,4,FALSE)))*Straight+(IF(B3>VLOOKUP(C3,Data,9,FALSE),1,IF(B3>VLOOKUP(C3,Data,8,FALSE),(B3-VLOOKUP(C3,Data,8,FALSE))/VLOOKUP(C3,Data,6,FALSE),0)))*Straight)-VLOOKUP(C3,Data,2,FALSE)*SIN(RADIANS(180*(IF(B3>VLOOKUP(C3,Data,8,FALSE),1,IF(B3>VLOOKUP(C3,Data,4,FALSE),(B3-VLOOKUP(C3,Data,4,FALSE))/VLOOKUP(C3,Data,5,FALSE),0)))+180*(IF(B3>VLOOKUP(C3,Data,10,FALSE),1,IF(B3>VLOOKUP(C3,Data,9,FALSE),(B3-VLOOKUP(C3,Data,9,FALSE))/VLOOKUP(C3,Data,7,FALSE),0))))) -> 76.89 | E3: =-VLOOKUP(C3,Data,2,FALSE)*COS(RADIANS(180*(IF(B3>VLOOKUP(C3,Data,8,FALSE),1,IF(B3>VLOOKUP(C3,Data,4,FALSE),(B3-VLOOKUP(C3,Data,4,FALSE))/VLOOKUP(C3,Data,5,FALSE),0)))+180*(IF(B3>VLOOKUP(C3,Data,10,FALSE),1,IF(B3>VLOOKUP(C3,Data,9,FALSE),(B3-VLOOKUP(C3,Data,9,FALSE))/VLOOKUP(C3,Data,7,FALSE),0))))) -> -38.99 | G3: 0 | H3: 2 | I3: =(Straight-(IF(G3>VLOOKUP(H3,Data,4,FALSE),1,G3/VLOOKUP(H3,Data,4,FALSE)))*Straight+(IF(G3>VLOOKUP(H3,Data,9,FALSE),1,IF(G3>VLOOKUP(H3,Data,8,FALSE),(G3-VLOOKUP(H3,Data,8,FALSE))/VLOOKUP(H3,Data,6,FALSE),0)))*Straight)-VLOOKUP(H3,Data,2,FALSE)*SIN(RADIANS(180*(IF(G3>VLOOKUP(H3,Data,8,FALSE),1,IF(G3>VLOOKUP(H3,Data,4,FALSE),(G3-VLOOKUP(H3,Data,4,FALSE))/VLOOKUP(H3,Data,5,FALSE),0)))+180*(IF(G3>VLOOKUP(H3,Data,10,FALSE),1,IF(G3>VLOOKUP(H3,Data,9,FALSE),(G3-VLOOKUP(H3,Data,9,FALSE))/VLOOKUP(H3,Data,7,FALSE),0))))) -> 76.89 | J3: =-VLOOKUP(H3,Data,2,FALSE)*COS(RADIANS(180*(IF(G3>VLOOKUP(H3,Data,8,FALSE),1,IF(G3>VLOOKUP(H3,Data,4,FALSE),(G3-VLOOKUP(H3,Data,4,FALSE))/VLOOKUP(H3,Data,5,FALSE),0)))+180*(IF(G3>VLOOKUP(H3,Data,10,FALSE),1,IF(G3>VLOOKUP(H3,Data,9,FALSE),(G3-VLOOKUP(H3,Data,9,FALSE))/VLOOKUP(H3,Data,7,FALSE),0))))) -> -40.21 | L3: 0 | M3: 3 | N3: =(Straight-(IF(L3>VLOOKUP(M3,Data,4,FALSE),1,L3/VLOOKUP(M3,Data,4,FALSE)))*Straight+(IF(L3>VLOOKUP(M3,Data,9,FALSE),1,IF(L3>VLOOKUP(M3,Data,8,FALSE),(L3-VLOOKUP(M3,Data,8,FALSE))/VLOOKUP(M3,Data,6,FALSE),0)))*Straight)-VLOOKUP(M3,Data,2,FALSE)*SIN(RADIANS(180*(IF(L3>VLOOKUP(M3,Data,8,FALSE),1,IF(L3>VLOOKUP(M3,Data,4,FALSE),(L3-VLOOKUP(M3,Data,4,FALSE))/VLOOKUP(M3,Data,5,FALSE),0)))+180*(IF(L3>VLOOKUP(M3,Data,10,FALSE),1,IF(L3>VLOOKUP(M3,Data,9,FALSE),(L3-VLOOKUP(M3,Data,9,FALSE))/VLOOKUP(M3,Data,7,FALSE),0))))) -> 76.89 | O3: =-VLOOKUP(M3,Data,2,FALSE)*COS(RADIANS(180*(IF(L3>VLOOKUP(M3,Data,8,FALSE),1,IF(L3>VLOOKUP(M3,Data,4,FALSE),(L3-VLOOKUP(M3,Data,4,FALSE))/VLOOKUP(M3,Data,5,FALSE),0)))+180*(IF(L3>VLOOKUP(M3,Data,10,FALSE),1,IF(L3>VLOOKUP(M3,Data,9,FALSE),(L3-VLOOKUP(M3,Data,9,FALSE))/VLOOKUP(M3,Data,7,FALSE),0))))) -> -41.43 | Q3: 0 | R3: 4 | S3: =(Straight-(IF(Q3>VLOOKUP(R3,Data,4,FALSE),1,Q3/VLOOKUP(R3,Data,4,FALSE)))*Straight+(IF(Q3>VLOOKUP(R3,Data,9,FALSE),1,IF(Q3>VLOOKUP(R3,Data,8,FALSE),(Q3-VLOOKUP(R3,Data,8,FALSE))/VLOOKUP(R3,Data,6,FALSE),0)))*Straight)-VLOOKUP(R3,Data,2,FALSE)*SIN(RADIANS(180*(IF(Q3>VLOOKUP(R3,Data,8,FALSE),1,IF(Q3>VLOOKUP(R3,Data,4,FALSE),(Q3-VLOOKUP(R3,Data,4,FALSE))/VLOOKUP(R3,Data,5,FALSE),0)))+180*(IF(Q3>VLOOKUP(R3,Data,10,FALSE),1,IF(Q3>VLOOKUP(R3,Data,9,FALSE),(Q3-VLOOKUP(R3,Data,9,FALSE))/VLOOKUP(R3,Data,7,FALSE),0))))) -> 76.89 | T3: =-VLOOKUP(R3,Data,2,FALSE)*COS(RADIANS(180*(IF(Q3>VLOOKUP(R3,Data,8,FALSE),1,IF(Q3>VLOOKUP(R3,Data,4,FALSE),(Q3-VLOOKUP(R3,Data,4,FALSE))/VLOOKUP(R3,Data,5,FALSE),0)))+180*(IF(Q3>VLOOKUP(R3,Data,10,FALSE),1,IF(Q3>VLOOKUP(R3,Data,9,FALSE),(Q3-VLOOKUP(R3,Data,9,FALSE))/VLOOKUP(R3,Data,7,FALSE),0))))) -> -42.65 | V3: 0 | W3: 5 | X3: =(Straight-(IF(V3>VLOOKUP(W3,Data,4,FALSE),1,V3/VLOOKUP(W3,Data,4,FALSE)))*Straight+(IF(V3>VLOOKUP(W3,Data,9,FALSE),1,IF(V3>VLOOKUP(W3,Data,8,FALSE),(V3-VLOOKUP(W3,Data,8,FALSE))/VLOOKUP(W3,Data,6,FALSE),0)))*Straight)-VLOOKUP(W3,Data,2,FALSE)*SIN(RADIANS(180*(IF(V3>VLOOKUP(W3,Data,8,FALSE),1,IF(V3>VLOOKUP(W3,Data,4,FALSE),(V3-VLOOKUP(W3,Data,4,FALSE))/VLOOKUP(W3,Data,5,FALSE),0)))+180*(IF(V3>VLOOKUP(W3,Data,10,FALSE),1,IF(V3>VLOOKUP(W3,Data,9,FALSE),(V3-VLOOKUP(W3,Data,9,FALSE))/VLOOKUP(W3,Data,7,FALSE),0))))) -> 76.89 | Y3: =-VLOOKUP(W3,Data,2,FALSE)*COS(RADIANS(180*(IF(V3>VLOOKUP(W3,Data,8,FALSE),1,IF(V3>VLOOKUP(W3,Data,4,FALSE),(V3-VLOOKUP(W3,Data,4,FALSE))/VLOOKUP(W3,Data,5,FALSE),0)))+180*(IF(V3>VLOOKUP(W3,Data,10,FALSE),1,IF(V3>VLOOKUP(W3,Data,9,FALSE),(V3-VLOOKUP(W3,Data,9,FALSE))/VLOOKUP(W3,Data,7,FALSE),0))))) -> -43.87 | AA3: 0 | AB3: 6 | AC3: =(Straight-(IF(AA3>VLOOKUP(AB3,Data,4,FALSE),1,AA3/VLOOKUP(AB3,Data,4,FALSE)))*Straight+(IF(AA3>VLOOKUP(AB3,Data,9,FALSE),1,IF(AA3>VLOOKUP(AB3,Data,8,FALSE),(AA3-VLOOKUP(AB3,Data,8,FALSE))/VLOOKUP(AB3,Data,6,FALSE),0)))*Straight)-VLOOKUP(AB3,Data,2,FALSE)*SIN(RADIANS(180*(IF(AA3>VLOOKUP(AB3,Data,8,FALSE),1,IF(AA3>VLOOKUP(AB3,Data,4,FALSE),(AA3-VLOOKUP(AB3,Data,4,FALSE))/VLOOKUP(AB3,Data,5,FALSE),0)))+180*(IF(AA3>VLOOKUP(AB3,Data,10,FALSE),1,IF(AA3>VLOOKUP(AB3,Data,9,FALSE),(AA3-VLOOKUP(AB3,Data,9,FALSE))/VLOOKUP(AB3,Data,7,FALSE),0))))) -> 76.89 | AD3: =-VLOOKUP(AB3,Data,2,FALSE)*COS(RADIANS(180*(IF(AA3>VLOOKUP(AB3,Data,8,FALSE),1,IF(AA3>VLOOKUP(AB3,Data,4,FALSE),(AA3-VLOOKUP(AB3,Data,4,FALSE))/VLOOKUP(AB3,Data,5,FALSE),0)))+180*(IF(AA3>VLOOKUP(AB3,Data,10,FALSE),1,IF(AA3>VLOOKUP(AB3,Data,9,FALSE),(AA3-VLOOKUP(AB3,Data,9,FALSE))/VLOOKUP(AB3,Data,7,FALSE),0))))) -> -45.09 | AF3: 0 | AG3: 7 | AH3: =(Straight-(IF(AF3>VLOOKUP(AG3,Data,4,FALSE),1,AF3/VLOOKUP(AG3,Data,4,FALSE)))*Straight+(IF(AF3>VLOOKUP(AG3,Data,9,FALSE),1,IF(AF3>VLOOKUP(AG3,Data,8,FALSE),(AF3-VLOOKUP(AG3,Data,8,FALSE))/VLOOKUP(AG3,Data,6,FALSE),0)))*Straight)-VLOOKUP(AG3,Data,2,FALSE)*SIN(RADIANS(180*(IF(AF3>VLOOKUP(AG3,Data,8,FALSE),1,IF(AF3>VLOOKUP(AG3,Data,4,FALSE),(AF3-VLOOKUP(AG3,Data,4,FALSE))/VLOOKUP(AG3,Data,5,FALSE),0)))+180*(IF(AF3>VLOOKUP(AG3,Data,10,FALSE),1,IF(AF3>VLOOKUP(AG3,Data,9,FALSE),(AF3-VLOOKUP(AG3,Data,9,FALSE))/VLOOKUP(AG3,Data,7,FALSE),0))))) -> 76.89 | AI3: =-VLOOKUP(AG3,Data,2,FALSE)*COS(RADIANS(180*(IF(AF3>VLOOKUP(AG3,Data,8,FALSE),1,IF(AF3>VLOOKUP(AG3,Data,4,FALSE),(AF3-VLOOKUP(AG3,Data,4,FALSE))/VLOOKUP(AG3,Data,5,FALSE),0)))+180*(IF(AF3>VLOOKUP(AG3,Data,10,FALSE),1,IF(AF3>VLOOKUP(AG3,Data,9,FALSE),(AF3-VLOOKUP(AG3,Data,9,FALSE))/VLOOKUP(AG3,Data,7,FALSE),0))))) -> -46.31 | AK3: 0 | AL3: 8 | AM3: =(Straight-(IF(AK3>VLOOKUP(AL3,Data,4,FALSE),1,AK3/VLOOKUP(AL3,Data,4,FALSE)))*Straight+(IF(AK3>VLOOKUP(AL3,Data,9,FALSE),1,IF(AK3>VLOOKUP(AL3,Data,8,FALSE),(AK3-VLOOKUP(AL3,Data,8,FALSE))/VLOOKUP(AL3,Data,6,FALSE),0)))*Straight)-VLOOKUP(AL3,Data,2,FALSE)*SIN(RADIANS(180*(IF(AK3>VLOOKUP(AL3,Data,8,FALSE),1,IF(AK3>VLOOKUP(AL3,Data,4,FALSE),(AK3-VLOOKUP(AL3,Data,4,FALSE))/VLOOKUP(AL3,Data,5,FALSE),0)))+180*(IF(AK3>VLOOKUP(AL3,Data,10,FALSE),1,IF(AK3>VLOOKUP(AL3,Data,9,FALSE),(AK3-VLOOKUP(AL3,Data,9,FALSE))/VLOOKUP(AL3,Data,7,FALSE),0))))) -> 76.89 | AN3: =-VLOOKUP(AL3,Data,2,FALSE)*COS(RADIANS(180*(IF(AK3>VLOOKUP(AL3,Data,8,FALSE),1,IF(AK3>VLOOKUP(AL3,Data,4,FALSE),(AK3-VLOOKUP(AL3,Data,4,FALSE))/VLOOKUP(AL3,Data,5,FALSE),0)))+180*(IF(AK3>VLOOKUP(AL3,Data,10,FALSE),1,IF(AK3>VLOOKUP(AL3,Data,9,FALSE),(AK3-VLOOKUP(AL3,Data,9,FALSE))/VLOOKUP(AL3,Data,7,FALSE),0))))) -> -47.53 | AP3: 0 | AQ3: 9 | AR3: =(Straight-(IF(AP3>VLOOKUP(AQ3,Data,4,FALSE),1,AP3/VLOOKUP(AQ3,Data,4,FALSE)))*Straight+(IF(AP3>VLOOKUP(AQ3,Data,9,FALSE),1,IF(AP3>VLOOKUP(AQ3,Data,8,FALSE),(AP3-VLOOKUP(AQ3,Data,8,FALSE))/VLOOKUP(AQ3,Data,6,FALSE),0)))*Straight)-VLOOKUP(AQ3,Data,2,FALSE)*SIN(RADIANS(180*(IF(AP3>VLOOKUP(AQ3,Data,8,FALSE),1,IF(AP3>VLOOKUP(AQ3,Data,4,FALSE),(AP3-VLOOKUP(AQ3,Data,4,FALSE))/VLOOKUP(AQ3,Data,5,FALSE),0)))+180*(IF(AP3>VLOOKUP(AQ3,Data,10,FALSE),1,IF(AP3>VLOOKUP(AQ3,Data,9,FALSE),(AP3-VLOOKUP(AQ3,Data,9,FALSE))/VLOOKUP(AQ3,Data,7,FALSE),0))))) -> 76.89 | AS3: =-VLOOKUP(AQ3,Data,2,FALSE)*COS(RADIANS(180*(IF(AP3>VLOOKUP(AQ3,Data,8,FALSE),1,IF(AP3>VLOOKUP(AQ3,Data,4,FALSE),(AP3-VLOOKUP(AQ3,Data,4,FALSE))/VLOOKUP(AQ3,Data,5,FALSE),0)))+180*(IF(AP3>VLOOKUP(AQ3,Data,10,FALSE),1,IF(AP3>VLOOKUP(AQ3,Data,9,FALSE),(AP3-VLOOKUP(AQ3,Data,9,FALSE))/VLOOKUP(AQ3,Data,7,FALSE),0))))) -> -48.75 | AT3: 0 | AU3: 1 | AV3: =(Straight-(IF(AT3>VLOOKUP(AU3,Data,4,FALSE),1,AT3/VLOOKUP(AU3,Data,4,FALSE)))*Straight+(IF(AT3>VLOOKUP(AU3,Data,9,FALSE),1,IF(AT3>VLOOKUP(AU3,Data,8,FALSE),(AT3-VLOOKUP(AU3,Data,8,FALSE))/VLOOKUP(AU3,Data,6,FALSE),0)))*Straight)-VLOOKUP(AU3,Data,2,FALSE)*SIN(RADIANS(180*(IF(AT3>VLOOKUP(AU3,Data,8,FALSE),1,IF(AT3>VLOOKUP(AU3,Data,4,FALSE),(AT3-VLOOKUP(AU3,Data,4,FALSE))/VLOOKUP(AU3,Data,5,FALSE),0)))+180*(IF(AT3>VLOOKUP(AU3,Data,10,FALSE),1,IF(AT3>VLOOKUP(AU3,Data,9,FALSE),(AT3-VLOOKUP(AU3,Data,9,FALSE))/VLOOKUP(AU3,Data,7,FALSE),0))))) -> 76.89 | AW3: =-VLOOKUP(AU3,Data,2,FALSE)*COS(RADIANS(180*(IF(AT3>VLOOKUP(AU3,Data,8,FALSE),1,IF(AT3>VLOOKUP(AU3,Data,4,FALSE),(AT3-VLOOKUP(AU3,Data,4,FALSE))/VLOOKUP(AU3,Data,5,FALSE),0)))+180*(IF(AT3>VLOOKUP(AU3,Data,10,FALSE),1,IF(AT3>VLOOKUP(AU3,Data,9,FALSE),(AT3-VLOOKUP(AU3,Data,9,FALSE))/VLOOKUP(AU3,Data,7,FALSE),0))))) -> -38.99 | AX3: -23.11 | AY3: =-Radius -> -38.99
B4: =Straight -> 76.89 | C4: =C3 -> 1 | D4: =(Straight-(IF(B4>VLOOKUP(C4,Data,4,FALSE),1,B4/VLOOKUP(C4,Data,4,FALSE)))*Straight+(IF(B4>VLOOKUP(C4,Data,9,FALSE),1,IF(B4>VLOOKUP(C4,Data,8,FALSE),(B4-VLOOKUP(C4,Data,8,FALSE))/VLOOKUP(C4,Data,6,FALSE),0)))*Straight)-VLOOKUP(C4,Data,2,FALSE)*SIN(RADIANS(180*(IF(B4>VLOOKUP(C4,Data,8,FALSE),1,IF(B4>VLOOKUP(C4,Data,4,FALSE),(B4-VLOOKUP(C4,Data,4,FALSE))/VLOOKUP(C4,Data,5,FALSE),0)))+180*(IF(B4>VLOOKUP(C4,Data,10,FALSE),1,IF(B4>VLOOKUP(C4,Data,9,FALSE),(B4-VLOOKUP(C4,Data,9,FALSE))/VLOOKUP(C4,Data,7,FALSE),0))))) -> 0 | E4: =-VLOOKUP(C4,Data,2,FALSE)*COS(RADIANS(180*(IF(B4>VLOOKUP(C4,Data,8,FALSE),1,IF(B4>VLOOKUP(C4,Data,4,FALSE),(B4-VLOOKUP(C4,Data,4,FALSE))/VLOOKUP(C4,Data,5,FALSE),0)))+180*(IF(B4>VLOOKUP(C4,Data,10,FALSE),1,IF(B4>VLOOKUP(C4,Data,9,FALSE),(B4-VLOOKUP(C4,Data,9,FALSE))/VLOOKUP(C4,Data,7,FALSE),0))))) -> -38.99 | G4: =Straight -> 76.89 | H4: =H3 -> 2 | I4: =(Straight-(IF(G4>VLOOKUP(H4,Data,4,FALSE),1,G4/VLOOKUP(H4,Data,4,FALSE)))*Straight+(IF(G4>VLOOKUP(H4,Data,9,FALSE),1,IF(G4>VLOOKUP(H4,Data,8,FALSE),(G4-VLOOKUP(H4,Data,8,FALSE))/VLOOKUP(H4,Data,6,FALSE),0)))*Straight)-VLOOKUP(H4,Data,2,FALSE)*SIN(RADIANS(180*(IF(G4>VLOOKUP(H4,Data,8,FALSE),1,IF(G4>VLOOKUP(H4,Data,4,FALSE),(G4-VLOOKUP(H4,Data,4,FALSE))/VLOOKUP(H4,Data,5,FALSE),0)))+180*(IF(G4>VLOOKUP(H4,Data,10,FALSE),1,IF(G4>VLOOKUP(H4,Data,9,FALSE),(G4-VLOOKUP(H4,Data,9,FALSE))/VLOOKUP(H4,Data,7,FALSE),0))))) -> 0 | J4: =-VLOOKUP(H4,Data,2,FALSE)*COS(RADIANS(180*(IF(G4>VLOOKUP(H4,Data,8,FALSE),1,IF(G4>VLOOKUP(H4,Data,4,FALSE),(G4-VLOOKUP(H4,Data,4,FALSE))/VLOOKUP(H4,Data,5,FALSE),0)))+180*(IF(G4>VLOOKUP(H4,Data,10,FALSE),1,IF(G4>VLOOKUP(H4,Data,9,FALSE),(G4-VLOOKUP(H4,Data,9,FALSE))/VLOOKUP(H4,Data,7,FALSE),0))))) -> -40.21 | L4: =Straight -> 76.89 | M4: =M3 -> 3 | N4: =(Straight-(IF(L4>VLOOKUP(M4,Data,4,FALSE),1,L4/VLOOKUP(M4,Data,4,FALSE)))*Straight+(IF(L4>VLOOKUP(M4,Data,9,FALSE),1,IF(L4>VLOOKUP(M4,Data,8,FALSE),(L4-VLOOKUP(M4,Data,8,FALSE))/VLOOKUP(M4,Data,6,FALSE),0)))*Straight)-VLOOKUP(M4,Data,2,FALSE)*SIN(RADIANS(180*(IF(L4>VLOOKUP(M4,Data,8,FALSE),1,IF(L4>VLOOKUP(M4,Data,4,FALSE),(L4-VLOOKUP(M4,Data,4,FALSE))/VLOOKUP(M4,Data,5,FALSE),0)))+180*(IF(L4>VLOOKUP(M4,Data,10,FALSE),1,IF(L4>VLOOKUP(M4,Data,9,FALSE),(L4-VLOOKUP(M4,Data,9,FALSE))/VLOOKUP(M4,Data,7,FALSE),0))))) -> 0 | O4: =-VLOOKUP(M4,Data,2,FALSE)*COS(RADIANS(180*(IF(L4>VLOOKUP(M4,Data,8,FALSE),1,IF(L4>VLOOKUP(M4,Data,4,FALSE),(L4-VLOOKUP(M4,Data,4,FALSE))/VLOOKUP(M4,Data,5,FALSE),0)))+180*(IF(L4>VLOOKUP(M4,Data,10,FALSE),1,IF(L4>VLOOKUP(M4,Data,9,FALSE),(L4-VLOOKUP(M4,Data,9,FALSE))/VLOOKUP(M4,Data,7,FALSE),0))))) -> -41.43 | Q4: =Straight -> 76.89 | R4: =R3 -> 4 | S4: =(Straight-(IF(Q4>VLOOKUP(R4,Data,4,FALSE),1,Q4/VLOOKUP(R4,Data,4,FALSE)))*Straight+(IF(Q4>VLOOKUP(R4,Data,9,FALSE),1,IF(Q4>VLOOKUP(R4,Data,8,FALSE),(Q4-VLOOKUP(R4,Data,8,FALSE))/VLOOKUP(R4,Data,6,FALSE),0)))*Straight)-VLOOKUP(R4,Data,2,FALSE)*SIN(RADIANS(180*(IF(Q4>VLOOKUP(R4,Data,8,FALSE),1,IF(Q4>VLOOKUP(R4,Data,4,FALSE),(Q4-VLOOKUP(R4,Data,4,FALSE))/VLOOKUP(R4,Data,5,FALSE),0)))+180*(IF(Q4>VLOOKUP(R4,Data,10,FALSE),1,IF(Q4>VLOOKUP(R4,Data,9,FALSE),(Q4-VLOOKUP(R4,Data,9,FALSE))/VLOOKUP(R4,Data,7,FALSE),0))))) -> 0 | T4: =-VLOOKUP(R4,Data,2,FALSE)*COS(RADIANS(180*(IF(Q4>VLOOKUP(R4,Data,8,FALSE),1,IF(Q4>VLOOKUP(R4,Data,4,FALSE),(Q4-VLOOKUP(R4,Data,4,FALSE))/VLOOKUP(R4,Data,5,FALSE),0)))+180*(IF(Q4>VLOOKUP(R4,Data,10,FALSE),1,IF(Q4>VLOOKUP(R4,Data,9,FALSE),(Q4-VLOOKUP(R4,Data,9,FALSE))/VLOOKUP(R4,Data,7,FALSE),0))))) -> -42.65 | V4: =Straight -> 76.89 | W4: =W3 -> 5 | X4: =(Straight-(IF(V4>VLOOKUP(W4,Data,4,FALSE),1,V4/VLOOKUP(W4,Data,4,FALSE)))*Straight+(IF(V4>VLOOKUP(W4,Data,9,FALSE),1,IF(V4>VLOOKUP(W4,Data,8,FALSE),(V4-VLOOKUP(W4,Data,8,FALSE))/VLOOKUP(W4,Data,6,FALSE),0)))*Straight)-VLOOKUP(W4,Data,2,FALSE)*SIN(RADIANS(180*(IF(V4>VLOOKUP(W4,Data,8,FALSE),1,IF(V4>VLOOKUP(W4,Data,4,FALSE),(V4-VLOOKUP(W4,Data,4,FALSE))/VLOOKUP(W4,Data,5,FALSE),0)))+180*(IF(V4>VLOOKUP(W4,Data,10,FALSE),1,IF(V4>VLOOKUP(W4,Data,9,FALSE),(V4-VLOOKUP(W4,Data,9,FALSE))/VLOOKUP(W4,Data,7,FALSE),0))))) -> 0 | Y4: =-VLOOKUP(W4,Data,2,FALSE)*COS(RADIANS(180*(IF(V4>VLOOKUP(W4,Data,8,FALSE),1,IF(V4>VLOOKUP(W4,Data,4,FALSE),(V4-VLOOKUP(W4,Data,4,FALSE))/VLOOKUP(W4,Data,5,FALSE),0)))+180*(IF(V4>VLOOKUP(W4,Data,10,FALSE),1,IF(V4>VLOOKUP(W4,Data,9,FALSE),(V4-VLOOKUP(W4,Data,9,FALSE))/VLOOKUP(W4,Data,7,FALSE),0))))) -> -43.87 | AA4: =Straight -> 76.89 | AB4: =AB3 -> 6 | AC4: =(Straight-(IF(AA4>VLOOKUP(AB4,Data,4,FALSE),1,AA4/VLOOKUP(AB4,Data,4,FALSE)))*Straight+(IF(AA4>VLOOKUP(AB4,Data,9,FALSE),1,IF(AA4>VLOOKUP(AB4,Data,8,FALSE),(AA4-VLOOKUP(AB4,Data,8,FALSE))/VLOOKUP(AB4,Data,6,FALSE),0)))*Straight)-VLOOKUP(AB4,Data,2,FALSE)*SIN(RADIANS(180*(IF(AA4>VLOOKUP(AB4,Data,8,FALSE),1,IF(AA4>VLOOKUP(AB4,Data,4,FALSE),(AA4-VLOOKUP(AB4,Data,4,FALSE))/VLOOKUP(AB4,Data,5,FALSE),0)))+180*(IF(AA4>VLOOKUP(AB4,Data,10,FALSE),1,IF(AA4>VLOOKUP(AB4,Data,9,FALSE),(AA4-VLOOKUP(AB4,Data,9,FALSE))/VLOOKUP(AB4,Data,7,FALSE),0))))) -> 0 | AD4: =-VLOOKUP(AB4,Data,2,FALSE)*COS(RADIANS(180*(IF(AA4>VLOOKUP(AB4,Data,8,FALSE),1,IF(AA4>VLOOKUP(AB4,Data,4,FALSE),(AA4-VLOOKUP(AB4,Data,4,FALSE))/VLOOKUP(AB4,Data,5,FALSE),0)))+180*(IF(AA4>VLOOKUP(AB4,Data,10,FALSE),1,IF(AA4>VLOOKUP(AB4,Data,9,FALSE),(AA4-VLOOKUP(AB4,Data,9,FALSE))/VLOOKUP(AB4,Data,7,FALSE),0))))) -> -45.09 | AF4: =Straight -> 76.89 | AG4: =AG3 -> 7 | AH4: =(Straight-(IF(AF4>VLOOKUP(AG4,Data,4,FALSE),1,AF4/VLOOKUP(AG4,Data,4,FALSE)))*Straight+(IF(AF4>VLOOKUP(AG4,Data,9,FALSE),1,IF(AF4>VLOOKUP(AG4,Data,8,FALSE),(AF4-VLOOKUP(AG4,Data,8,FALSE))/VLOOKUP(AG4,Data,6,FALSE),0)))*Straight)-VLOOKUP(AG4,Data,2,FALSE)*SIN(RADIANS(180*(IF(AF4>VLOOKUP(AG4,Data,8,FALSE),1,IF(AF4>VLOOKUP(AG4,Data,4,FALSE),(AF4-VLOOKUP(AG4,Data,4,FALSE))/VLOOKUP(AG4,Data,5,FALSE),0)))+180*(IF(AF4>VLOOKUP(AG4,Data,10,FALSE),1,IF(AF4>VLOOKUP(AG4,Data,9,FALSE),(AF4-VLOOKUP(AG4,Data,9,FALSE))/VLOOKUP(AG4,Data,7,FALSE),0))))) -> 0 | AI4: =-VLOOKUP(AG4,Data,2,FALSE)*COS(RADIANS(180*(IF(AF4>VLOOKUP(AG4,Data,8,FALSE),1,IF(AF4>VLOOKUP(AG4,Data,4,FALSE),(AF4-VLOOKUP(AG4,Data,4,FALSE))/VLOOKUP(AG4,Data,5,FALSE),0)))+180*(IF(AF4>VLOOKUP(AG4,Data,10,FALSE),1,IF(AF4>VLOOKUP(AG4,Data,9,FALSE),(AF4-VLOOKUP(AG4,Data,9,FALSE))/VLOOKUP(AG4,Data,7,FALSE),0))))) -> -46.31 | AK4: =Straight -> 76.89 | AL4: =AL3 -> 8 | AM4: =(Straight-(IF(AK4>VLOOKUP(AL4,Data,4,FALSE),1,AK4/VLOOKUP(AL4,Data,4,FALSE)))*Straight+(IF(AK4>VLOOKUP(AL4,Data,9,FALSE),1,IF(AK4>VLOOKUP(AL4,Data,8,FALSE),(AK4-VLOOKUP(AL4,Data,8,FALSE))/VLOOKUP(AL4,Data,6,FALSE),0)))*Straight)-VLOOKUP(AL4,Data,2,FALSE)*SIN(RADIANS(180*(IF(AK4>VLOOKUP(AL4,Data,8,FALSE),1,IF(AK4>VLOOKUP(AL4,Data,4,FALSE),(AK4-VLOOKUP(AL4,Data,4,FALSE))/VLOOKUP(AL4,Data,5,FALSE),0)))+180*(IF(AK4>VLOOKUP(AL4,Data,10,FALSE),1,IF(AK4>VLOOKUP(AL4,Data,9,FALSE),(AK4-VLOOKUP(AL4,Data,9,FALSE))/VLOOKUP(AL4,Data,7,FALSE),0))))) -> 0 | AN4: =-VLOOKUP(AL4,Data,2,FALSE)*COS(RADIANS(180*(IF(AK4>VLOOKUP(AL4,Data,8,FALSE),1,IF(AK4>VLOOKUP(AL4,Data,4,FALSE),(AK4-VLOOKUP(AL4,Data,4,FALSE))/VLOOKUP(AL4,Data,5,FALSE),0)))+180*(IF(AK4>VLOOKUP(AL4,Data,10,FALSE),1,IF(AK4>VLOOKUP(AL4,Data,9,FALSE),(AK4-VLOOKUP(AL4,Data,9,FALSE))/VLOOKUP(AL4,Data,7,FALSE),0))))) -> -47.53 | AP4: =Straight -> 76.89 | AQ4: =AQ3 -> 9 | AR4: =(Straight-(IF(AP4>VLOOKUP(AQ4,Data,4,FALSE),1,AP4/VLOOKUP(AQ4,Data,4,FALSE)))*Straight+(IF(AP4>VLOOKUP(AQ4,Data,9,FALSE),1,IF(AP4>VLOOKUP(AQ4,Data,8,FALSE),(AP4-VLOOKUP(AQ4,Data,8,FALSE))/VLOOKUP(AQ4,Data,6,FALSE),0)))*Straight)-VLOOKUP(AQ4,Data,2,FALSE)*SIN(RADIANS(180*(IF(AP4>VLOOKUP(AQ4,Data,8,FALSE),1,IF(AP4>VLOOKUP(AQ4,Data,4,FALSE),(AP4-VLOOKUP(AQ4,Data,4,FALSE))/VLOOKUP(AQ4,Data,5,FALSE),0)))+180*(IF(AP4>VLOOKUP(AQ4,Data,10,FALSE),1,IF(AP4>VLOOKUP(AQ4,Data,9,FALSE),(AP4-VLOOKUP(AQ4,Data,9,FALSE))/VLOOKUP(AQ4,Data,7,FALSE),0))))) -> 0 | AS4: =-VLOOKUP(AQ4,Data,2,FALSE)*COS(RADIANS(180*(IF(AP4>VLOOKUP(AQ4,Data,8,FALSE),1,IF(AP4>VLOOKUP(AQ4,Data,4,FALSE),(AP4-VLOOKUP(AQ4,Data,4,FALSE))/VLOOKUP(AQ4,Data,5,FALSE),0)))+180*(IF(AP4>VLOOKUP(AQ4,Data,10,FALSE),1,IF(AP4>VLOOKUP(AQ4,Data,9,FALSE),(AP4-VLOOKUP(AQ4,Data,9,FALSE))/VLOOKUP(AQ4,Data,7,FALSE),0))))) -> -48.75 | AT4: 0 | AU4: 9 | AV4: =(Straight-(IF(AT4>VLOOKUP(AU4,Data,4,FALSE),1,AT4/VLOOKUP(AU4,Data,4,FALSE)))*Straight+(IF(AT4>VLOOKUP(AU4,Data,9,FALSE),1,IF(AT4>VLOOKUP(AU4,Data,8,FALSE),(AT4-VLOOKUP(AU4,Data,8,FALSE))/VLOOKUP(AU4,Data,6,FALSE),0)))*Straight)-VLOOKUP(AU4,Data,2,FALSE)*SIN(RADIANS(180*(IF(AT4>VLOOKUP(AU4,Data,8,FALSE),1,IF(AT4>VLOOKUP(AU4,Data,4,FALSE),(AT4-VLOOKUP(AU4,Data,4,FALSE))/VLOOKUP(AU4,Data,5,FALSE),0)))+180*(IF(AT4>VLOOKUP(AU4,Data,10,FALSE),1,IF(AT4>VLOOKUP(AU4,Data,9,FALSE),(AT4-VLOOKUP(AU4,Data,9,FALSE))/VLOOKUP(AU4,Data,7,FALSE),0))))) -> 76.89 | AW4: =-VLOOKUP(AU4,Data,2,FALSE)*COS(RADIANS(180*(IF(AT4>VLOOKUP(AU4,Data,8,FALSE),1,IF(AT4>VLOOKUP(AU4,Data,4,FALSE),(AT4-VLOOKUP(AU4,Data,4,FALSE))/VLOOKUP(AU4,Data,5,FALSE),0)))+180*(IF(AT4>VLOOKUP(AU4,Data,10,FALSE),1,IF(AT4>VLOOKUP(AU4,Data,9,FALSE),(AT4-VLOOKUP(AU4,Data,9,FALSE))/VLOOKUP(AU4,Data,7,FALSE),0))))) -> -48.75 | AX4: -23.11 | AY4: =-OutRadius -> -48.75
A5: 5 | B5: =B$4+VLOOKUP(Lanes!C5,Data,5,FALSE)*(A5/180) -> 80.309973 | C5: =C4 -> 1 | D5: =(Straight-(IF(B5>VLOOKUP(C5,Data,4,FALSE),1,B5/VLOOKUP(C5,Data,4,FALSE)))*Straight+(IF(B5>VLOOKUP(C5,Data,9,FALSE),1,IF(B5>VLOOKUP(C5,Data,8,FALSE),(B5-VLOOKUP(C5,Data,8,FALSE))/VLOOKUP(C5,Data,6,FALSE),0)))*Straight)-VLOOKUP(C5,Data,2,FALSE)*SIN(RADIANS(180*(IF(B5>VLOOKUP(C5,Data,8,FALSE),1,IF(B5>VLOOKUP(C5,Data,4,FALSE),(B5-VLOOKUP(C5,Data,4,FALSE))/VLOOKUP(C5,Data,5,FALSE),0)))+180*(IF(B5>VLOOKUP(C5,Data,10,FALSE),1,IF(B5>VLOOKUP(C5,Data,9,FALSE),(B5-VLOOKUP(C5,Data,9,FALSE))/VLOOKUP(C5,Data,7,FALSE),0))))) -> -3.3982024 | E5: =-VLOOKUP(C5,Data,2,FALSE)*COS(RADIANS(180*(IF(B5>VLOOKUP(C5,Data,8,FALSE),1,IF(B5>VLOOKUP(C5,Data,4,FALSE),(B5-VLOOKUP(C5,Data,4,FALSE))/VLOOKUP(C5,Data,5,FALSE),0)))+180*(IF(B5>VLOOKUP(C5,Data,10,FALSE),1,IF(B5>VLOOKUP(C5,Data,9,FALSE),(B5-VLOOKUP(C5,Data,9,FALSE))/VLOOKUP(C5,Data,7,FALSE),0))))) -> -38.841631 | F5: 5 | G5: =G$4+VLOOKUP(Lanes!H5,Data,5,FALSE)*(F5/180) -> 80.416438 | H5: =H4 -> 2 | I5: =(Straight-(IF(G5>VLOOKUP(H5,Data,4,FALSE),1,G5/VLOOKUP(H5,Data,4,FALSE)))*Straight+(IF(G5>VLOOKUP(H5,Data,9,FALSE),1,IF(G5>VLOOKUP(H5,Data,8,FALSE),(G5-VLOOKUP(H5,Data,8,FALSE))/VLOOKUP(H5,Data,6,FALSE),0)))*Straight)-VLOOKUP(H5,Data,2,FALSE)*SIN(RADIANS(180*(IF(G5>VLOOKUP(H5,Data,8,FALSE),1,IF(G5>VLOOKUP(H5,Data,4,FALSE),(G5-VLOOKUP(H5,Data,4,FALSE))/VLOOKUP(H5,Data,5,FALSE),0)))+180*(IF(G5>VLOOKUP(H5,Data,10,FALSE),1,IF(G5>VLOOKUP(H5,Data,9,FALSE),(G5-VLOOKUP(H5,Data,9,FALSE))/VLOOKUP(H5,Data,7,FALSE),0))))) -> -3.5045324 | J5: =-VLOOKUP(H5,Data,2,FALSE)*COS(RADIANS(180*(IF(G5>VLOOKUP(H5,Data,8,FALSE),1,IF(G5>VLOOKUP(H5,Data,4,FALSE),(G5-VLOOKUP(H5,Data,4,FALSE))/VLOOKUP(H5,Data,5,FALSE),0)))+180*(IF(G5>VLOOKUP(H5,Data,10,FALSE),1,IF(G5>VLOOKUP(H5,Data,9,FALSE),(G5-VLOOKUP(H5,Data,9,FALSE))/VLOOKUP(H5,Data,7,FALSE),0))))) -> -40.056989 | K5: 5 | L5: =L$4+VLOOKUP(Lanes!M5,Data,5,FALSE)*(K5/180) -> 80.522903 | M5: =M4 -> 3 | N5: =(Straight-(IF(L5>VLOOKUP(M5,Data,4,FALSE),1,L5/VLOOKUP(M5,Data,4,FALSE)))*Straight+(IF(L5>VLOOKUP(M5,Data,9,FALSE),1,IF(L5>VLOOKUP(M5,Data,8,FALSE),(L5-VLOOKUP(M5,Data,8,FALSE))/VLOOKUP(M5,Data,6,FALSE),0)))*Straight)-VLOOKUP(M5,Data,2,FALSE)*SIN(RADIANS(180*(IF(L5>VLOOKUP(M5,Data,8,FALSE),1,IF(L5>VLOOKUP(M5,Data,4,FALSE),(L5-VLOOKUP(M5,Data,4,FALSE))/VLOOKUP(M5,Data,5,FALSE),0)))+180*(IF(L5>VLOOKUP(M5,Data,10,FALSE),1,IF(L5>VLOOKUP(M5,Data,9,FALSE),(L5-VLOOKUP(M5,Data,9,FALSE))/VLOOKUP(M5,Data,7,FALSE),0))))) -> -3.6108624 | O5: =-VLOOKUP(M5,Data,2,FALSE)*COS(RADIANS(180*(IF(L5>VLOOKUP(M5,Data,8,FALSE),1,IF(L5>VLOOKUP(M5,Data,4,FALSE),(L5-VLOOKUP(M5,Data,4,FALSE))/VLOOKUP(M5,Data,5,FALSE),0)))+180*(IF(L5>VLOOKUP(M5,Data,10,FALSE),1,IF(L5>VLOOKUP(M5,Data,9,FALSE),(L5-VLOOKUP(M5,Data,9,FALSE))/VLOOKUP(M5,Data,7,FALSE),0))))) -> -41.272346 | P5: 5 | Q5: =Q$4+VLOOKUP(Lanes!R5,Data,5,FALSE)*(P5/180) -> 80.629368 | R5: =R4 -> 4 | S5: =(Straight-(IF(Q5>VLOOKUP(R5,Data,4,FALSE),1,Q5/VLOOKUP(R5,Data,4,FALSE)))*Straight+(IF(Q5>VLOOKUP(R5,Data,9,FALSE),1,IF(Q5>VLOOKUP(R5,Data,8,FALSE),(Q5-VLOOKUP(R5,Data,8,FALSE))/VLOOKUP(R5,Data,6,FALSE),0)))*Straight)-VLOOKUP(R5,Data,2,FALSE)*SIN(RADIANS(180*(IF(Q5>VLOOKUP(R5,Data,8,FALSE),1,IF(Q5>VLOOKUP(R5,Data,4,FALSE),(Q5-VLOOKUP(R5,Data,4,FALSE))/VLOOKUP(R5,Data,5,FALSE),0)))+180*(IF(Q5>VLOOKUP(R5,Data,10,FALSE),1,IF(Q5>VLOOKUP(R5,Data,9,FALSE),(Q5-VLOOKUP(R5,Data,9,FALSE))/VLOOKUP(R5,Data,7,FALSE),0))))) -> -3.7171924 | T5: =-VLOOKUP(R5,Data,2,FALSE)*COS(RADIANS(180*(IF(Q5>VLOOKUP(R5,Data,8,FALSE),1,IF(Q5>VLOOKUP(R5,Data,4,FALSE),(Q5-VLOOKUP(R5,Data,4,FALSE))/VLOOKUP(R5,Data,5,FALSE),0)))+180*(IF(Q5>VLOOKUP(R5,Data,10,FALSE),1,IF(Q5>VLOOKUP(R5,Data,9,FALSE),(Q5-VLOOKUP(R5,Data,9,FALSE))/VLOOKUP(R5,Data,7,FALSE),0))))) -> -42.487704 | U5: 5 | V5: =V$4+VLOOKUP(Lanes!W5,Data,5,FALSE)*(U5/180) -> 80.735833 | W5: =W4 -> 5 | X5: =(Straight-(IF(V5>VLOOKUP(W5,Data,4,FALSE),1,V5/VLOOKUP(W5,Data,4,FALSE)))*Straight+(IF(V5>VLOOKUP(W5,Data,9,FALSE),1,IF(V5>VLOOKUP(W5,Data,8,FALSE),(V5-VLOOKUP(W5,Data,8,FALSE))/VLOOKUP(W5,Data,6,FALSE),0)))*Straight)-VLOOKUP(W5,Data,2,FALSE)*SIN(RADIANS(180*(IF(V5>VLOOKUP(W5,Data,8,FALSE),1,IF(V5>VLOOKUP(W5,Data,4,FALSE),(V5-VLOOKUP(W5,Data,4,FALSE))/VLOOKUP(W5,Data,5,FALSE),0)))+180*(IF(V5>VLOOKUP(W5,Data,10,FALSE),1,IF(V5>VLOOKUP(W5,Data,9,FALSE),(V5-VLOOKUP(W5,Data,9,FALSE))/VLOOKUP(W5,Data,7,FALSE),0))))) -> -3.8235224 | Y5: =-VLOOKUP(W5,Data,2,FALSE)*COS(RADIANS(180*(IF(V5>VLOOKUP(W5,Data,8,FALSE),1,IF(V5>VLOOKUP(W5,Data,4,FALSE),(V5-VLOOKUP(W5,Data,4,FALSE))/VLOOKUP(W5,Data,5,FALSE),0)))+180*(IF(V5>VLOOKUP(W5,Data,10,FALSE),1,IF(V5>VLOOKUP(W5,Data,9,FALSE),(V5-VLOOKUP(W5,Data,9,FALSE))/VLOOKUP(W5,Data,7,FALSE),0))))) -> -43.703061 | Z5: 5 | AA5: =AA$4+VLOOKUP(Lanes!AB5,Data,5,FALSE)*(Z5/180) -> 80.842298 | AB5: =AB4 -> 6 | AC5: =(Straight-(IF(AA5>VLOOKUP(AB5,Data,4,FALSE),1,AA5/VLOOKUP(AB5,Data,4,FALSE)))*Straight+(IF(AA5>VLOOKUP(AB5,Data,9,FALSE),1,IF(AA5>VLOOKUP(AB5,Data,8,FALSE),(AA5-VLOOKUP(AB5,Data,8,FALSE))/VLOOKUP(AB5,Data,6,FALSE),0)))*Straight)-VLOOKUP(AB5,Data,2,FALSE)*SIN(RADIANS(180*(IF(AA5>VLOOKUP(AB5,Data,8,FALSE),1,IF(AA5>VLOOKUP(AB5,Data,4,FALSE),(AA5-VLOOKUP(AB5,Data,4,FALSE))/VLOOKUP(AB5,Data,5,FALSE),0)))+180*(IF(AA5>VLOOKUP(AB5,Data,10,FALSE),1,IF(AA5>VLOOKUP(AB5,Data,9,FALSE),(AA5-VLOOKUP(AB5,Data,9,FALSE))/VLOOKUP(AB5,Data,7,FALSE),0))))) -> -3.9298524 | AD5: =-VLOOKUP(AB5,Data,2,FALSE)*COS(RADIANS(180*(IF(AA5>VLOOKUP(AB5,Data,8,FALSE),1,IF(AA5>VLOOKUP(AB5,Data,4,FALSE),(AA5-VLOOKUP(AB5,Data,4,FALSE))/VLOOKUP(AB5,Data,5,FALSE),0)))+180*(IF(AA5>VLOOKUP(AB5,Data,10,FALSE),1,IF(AA5>VLOOKUP(AB5,Data,9,FALSE),(AA5-VLOOKUP(AB5,Data,9,FALSE))/VLOOKUP(AB5,Data,7,FALSE),0))))) -> -44.918419 | AE5: 5 | AF5: =AF$4+VLOOKUP(Lanes!AG5,Data,5,FALSE)*(AE5/180) -> 80.948763 | AG5: =AG4 -> 7 | AH5: =(Straight-(IF(AF5>VLOOKUP(AG5,Data,4,FALSE),1,AF5/VLOOKUP(AG5,Data,4,FALSE)))*Straight+(IF(AF5>VLOOKUP(AG5,Data,9,FALSE),1,IF(AF5>VLOOKUP(AG5,Data,8,FALSE),(AF5-VLOOKUP(AG5,Data,8,FALSE))/VLOOKUP(AG5,Data,6,FALSE),0)))*Straight)-VLOOKUP(AG5,Data,2,FALSE)*SIN(RADIANS(180*(IF(AF5>VLOOKUP(AG5,Data,8,FALSE),1,IF(AF5>VLOOKUP(AG5,Data,4,FALSE),(AF5-VLOOKUP(AG5,Data,4,FALSE))/VLOOKUP(AG5,Data,5,FALSE),0)))+180*(IF(AF5>VLOOKUP(AG5,Data,10,FALSE),1,IF(AF5>VLOOKUP(AG5,Data,9,FALSE),(AF5-VLOOKUP(AG5,Data,9,FALSE))/VLOOKUP(AG5,Data,7,FALSE),0))))) -> -4.0361824 | AI5: =-VLOOKUP(AG5,Data,2,FALSE)*COS(RADIANS(180*(IF(AF5>VLOOKUP(AG5,Data,8,FALSE),1,IF(AF5>VLOOKUP(AG5,Data,4,FALSE),(AF5-VLOOKUP(AG5,Data,4,FALSE))/VLOOKUP(AG5,Data,5,FALSE),0)))+180*(IF(AF5>VLOOKUP(AG5,Data,10,FALSE),1,IF(AF5>VLOOKUP(AG5,Data,9,FALSE),(AF5-VLOOKUP(AG5,Data,9,FALSE))/VLOOKUP(AG5,Data,7,FALSE),0))))) -> -46.133776 | AJ5: 5 | AK5: =AK$4+VLOOKUP(Lanes!AL5,Data,5,FALSE)*(AJ5/180) -> 81.055228 | AL5: =AL4 -> 8 | AM5: =(Straight-(IF(AK5>VLOOKUP(AL5,Data,4,FALSE),1,AK5/VLOOKUP(AL5,Data,4,FALSE)))*Straight+(IF(AK5>VLOOKUP(AL5,Data,9,FALSE),1,IF(AK5>VLOOKUP(AL5,Data,8,FALSE),(AK5-VLOOKUP(AL5,Data,8,FALSE))/VLOOKUP(AL5,Data,6,FALSE),0)))*Straight)-VLOOKUP(AL5,Data,2,FALSE)*SIN(RADIANS(180*(IF(AK5>VLOOKUP(AL5,Data,8,FALSE),1,IF(AK5>VLOOKUP(AL5,Data,4,FALSE),(AK5-VLOOKUP(AL5,Data,4,FALSE))/VLOOKUP(AL5,Data,5,FALSE),0)))+180*(IF(AK5>VLOOKUP(AL5,Data,10,FALSE),1,IF(AK5>VLOOKUP(AL5,Data,9,FALSE),(AK5-VLOOKUP(AL5,Data,9,FALSE))/VLOOKUP(AL5,Data,7,FALSE),0))))) -> -4.1425125 | AN5: =-VLOOKUP(AL5,Data,2,FALSE)*COS(RADIANS(180*(IF(AK5>VLOOKUP(AL5,Data,8,FALSE),1,IF(AK5>VLOOKUP(AL5,Data,4,FALSE),(AK5-VLOOKUP(AL5,Data,4,FALSE))/VLOOKUP(AL5,Data,5,FALSE),0)))+180*(IF(AK5>VLOOKUP(AL5,Data,10,FALSE),1,IF(AK5>VLOOKUP(AL5,Data,9,FALSE),(AK5-VLOOKUP(AL5,Data,9,FALSE))/VLOOKUP(AL5,Data,7,FALSE),0))))) -> -47.349134 | AO5: 5 | AP5: =AP$4+VLOOKUP(Lanes!AQ5,Data,5,FALSE)*(AO5/180) -> 81.161693 | AQ5: =AQ4 -> 9 | AR5: =(Straight-(IF(AP5>VLOOKUP(AQ5,Data,4,FALSE),1,AP5/VLOOKUP(AQ5,Data,4,FALSE)))*Straight+(IF(AP5>VLOOKUP(AQ5,Data,9,FALSE),1,IF(AP5>VLOOKUP(AQ5,Data,8,FALSE),(AP5-VLOOKUP(AQ5,Data,8,FALSE))/VLOOKUP(AQ5,Data,6,FALSE),0)))*Straight)-VLOOKUP(AQ5,Data,2,FALSE)*SIN(RADIANS(180*(IF(AP5>VLOOKUP(AQ5,Data,8,FALSE),1,IF(AP5>VLOOKUP(AQ5,Data,4,FALSE),(AP5-VLOOKUP(AQ5,Data,4,FALSE))/VLOOKUP(AQ5,Data,5,FALSE),0)))+180*(IF(AP5>VLOOKUP(AQ5,Data,10,FALSE),1,IF(AP5>VLOOKUP(AQ5,Data,9,FALSE),(AP5-VLOOKUP(AQ5,Data,9,FALSE))/VLOOKUP(AQ5,Data,7,FALSE),0))))) -> -4.2488425 | AS5: =-VLOOKUP(AQ5,Data,2,FALSE)*COS(RADIANS(180*(IF(AP5>VLOOKUP(AQ5,Data,8,FALSE),1,IF(AP5>VLOOKUP(AQ5,Data,4,FALSE),(AP5-VLOOKUP(AQ5,Data,4,FALSE))/VLOOKUP(AQ5,Data,5,FALSE),0)))+180*(IF(AP5>VLOOKUP(AQ5,Data,10,FALSE),1,IF(AP5>VLOOKUP(AQ5,Data,9,FALSE),(AP5-VLOOKUP(AQ5,Data,9,FALSE))/VLOOKUP(AQ5,Data,7,FALSE),0))))) -> -48.564492 | AX5: Home Straight Lane 1
